from functools import partial
from unittest.mock import patch

import pytest
from crum import impersonate
from django.contrib.auth.models import AnonymousUser
from django.db import connection
from django.test import override_settings
from rest_framework.reverse import reverse

from ansible_base.lib.abstract_models.common import CommonModel, ImmutableModel
from test_app.models import EncryptionModel, ImmutableLogEntry, Organization, RelatedFieldsTestModel, User


@pytest.mark.django_db
def test_save_encryption():
    model = EncryptionModel.objects.create(testing1='c')
    model.save()

    saved_model = EncryptionModel.objects.first()
    assert saved_model.testing2 == 'b'
    assert saved_model.testing1 == 'c'


@pytest.mark.django_db
def test_name_in_summary_fields():
    model = EncryptionModel.objects.create()
    assert 'name' in model.summary_fields()


@override_settings(SYSTEM_USERNAME=None)
@pytest.mark.django_db
def test_save_attribution_no_system_username():
    model = Organization.objects.create(name='foo-org')

    model = Organization()
    model.save()
    assert model.created_by is None
    assert model.modified_by is None

    model.refresh_from_db()
    assert model.created_by is None
    assert model.modified_by is None


@pytest.mark.django_db
@override_settings(SYSTEM_USERNAME='_not_system')
def test_save_attribution_with_system_username_set_but_nonexistent_as_false(system_user, organization, expected_log):
    expected_log = partial(expected_log, "ansible_base.lib.abstract_models.common.logger")

    with expected_log("warn", "no user with that username exists", assert_not_called=True):
        organization.save()

    assert organization.created_by == system_user
    assert organization.modified_by is None

    organization.refresh_from_db()
    assert organization.created_by == system_user
    assert organization.modified_by is None


@pytest.mark.django_db
def test_save_attribution_with_system_user(system_user, organization):
    # This test looks weird, it's just testing a fixture, but it's because we
    # don't want to create objects manually here - otherwise deleting system_user at teardown
    # will trigger an IntegrityError because of the attribution fields of our object pointing
    # to it and the fact that we don't have on_delete=SET_NULL on those fields.
    assert organization.created_by == system_user
    assert organization.modified_by == system_user


@pytest.mark.django_db
def test_save_attribution_created_by_set_manually_and_retained(django_user_model, system_user, user, random_user):
    assert random_user.created_by == system_user
    assert random_user.modified_by == system_user

    random_user.created_by = user
    random_user.save()

    assert random_user.created_by == user
    assert random_user.modified_by == system_user

    random_user.refresh_from_db()
    assert random_user.created_by == user
    assert random_user.modified_by == system_user


@pytest.mark.django_db
def test_related_fields_view_resolution(shut_up_logging):
    model = RelatedFieldsTestModel.objects.create()

    with patch('ansible_base.lib.abstract_models.common.reverse') as reverse:
        model.related_fields(None)

    # First off, we should never have 'teams_with_no_view' as an arg to reverse
    for call in reverse.call_args_list:
        assert 'teams_with_no_view' not in call[0][0]

    # But it should have been called with related_fields_test_model-users-list
    # (default since we don't override it for the 'users' field)
    assert 'related_fields_test_model-users-list' in [call[0][0] for call in reverse.call_args_list]

    # And it should have been called with related_fields_test_model-more_teams-list
    # (overridden for the 'more_teams' field)
    assert 'related_fields_test_model-more_teams-list' in [call[0][0] for call in reverse.call_args_list]


@pytest.mark.django_db
def test_resave_of_model_with_no_created(expected_log, system_user):
    # Create a random model and save it without warning and no system user
    model = Organization()
    with override_settings(SYSTEM_USERNAME='_not_system'):
        model.save()

    assert model.created_by is None

    model.save()
    assert model.created_by is None

    model.delete()


def test_attributable_user_anonymous_user(system_user):
    # If we are an AnonymousUser and we call _attributable_error we should get the system user back
    model = User()
    with impersonate(AnonymousUser):
        model.save()

    assert model.created_by == system_user
    model.delete()


@pytest.mark.django_db
@pytest.mark.xfail(reason="https://github.com/ansible/django-ansible-base/issues/198")
def test_cascade_behavior_for_created_by(user, user_api_client):
    url = reverse('organization-list')
    r = user_api_client.post(url, data={'name': 'foo'})
    assert r.status_code == 201
    org = Organization.objects.get(id=r.data['id'])
    assert org.created_by == user
    user_id = user.id
    connection.check_constraints()  # issue replication - show constraint violation introduced
    user.delete()
    org.refresh_from_db()
    assert org.created_by_id == user_id
    connection.check_constraints()


@pytest.mark.django_db
def test_immutable_model_is_immutable():
    """
    ImmutableModel prevents saves from happening after the first save.
    """
    log_entry = ImmutableLogEntry(message="Oh no! An important message!")
    log_entry.save()  # We can save it once
    log_entry.message = "Oh no! An even more important message!"

    with pytest.raises(ValueError) as excinfo:
        log_entry.save()
    assert excinfo.value.args[0] == "ImmutableLogEntry is immutable and cannot be modified."

    # Ensure that nothing got updated before the exception was raised
    log_entry.refresh_from_db()
    assert log_entry.message == "Oh no! An important message!"


@pytest.mark.django_db
def test_immutable_model_mixin_must_be_first():
    """
    We raise an error if the ImmutableModel mixin is used improperly and doesn't come first.
    """
    with pytest.raises(ValueError) as excinfo:

        class FooModel(CommonModel, ImmutableModel):
            pass

    assert excinfo.value.args[0] == "ImmutableModel must be the first base class for FooModel"
